Workbook

Sheet Resumen
A1: Plan de pruebas — Vicaria de los Pobres, Pastoral de Adicciones
A2: Casos manuales (TC) y automatizados (TA) de los Sprint 1 a 4 (Sprint 4: frontend hecho con datos simulados, backend en curso; casos manuales Pendientes). Se actualiza con los contadores de las hojas.
A4: Tipo | B4: Sprint | C4: Total | D4: OK | E4: Falla | F4: Bloqueado | G4: Pendiente
A5: Manuales (TC) | B5: Sprint 1-2 | C5: =COUNTIF('Parte A - Manuales'!$B$2:$B$212,B5) | D5: =COUNTIFS('Parte A - Manuales'!$B$2:$B$212,B5,'Parte A - Manuales'!$J$2:$J$212,"OK") | E5: =COUNTIFS('Parte A - Manuales'!$B$2:$B$212,B5,'Parte A - Manuales'!$J$2:$J$212,"Falla") | F5: =COUNTIFS('Parte A - Manuales'!$B$2:$B$212,B5,'Parte A - Manuales'!$J$2:$J$212,"Bloqueado") | G5: =COUNTIFS('Parte A - Manuales'!$B$2:$B$212,B5,'Parte A - Manuales'!$J$2:$J$212,"Pendiente")
A6: Manuales (TC) | B6: Sprint 3 | C6: =COUNTIF('Parte A - Manuales'!$B$2:$B$212,B6) | D6: =COUNTIFS('Parte A - Manuales'!$B$2:$B$212,B6,'Parte A - Manuales'!$J$2:$J$212,"OK") | E6: =COUNTIFS('Parte A - Manuales'!$B$2:$B$212,B6,'Parte A - Manuales'!$J$2:$J$212,"Falla") | F6: =COUNTIFS('Parte A - Manuales'!$B$2:$B$212,B6,'Parte A - Manuales'!$J$2:$J$212,"Bloqueado") | G6: =COUNTIFS('Parte A - Manuales'!$B$2:$B$212,B6,'Parte A - Manuales'!$J$2:$J$212,"Pendiente")
A7: Manuales (TC) | B7: Sprint 4 | C7: =COUNTIF('Parte A - Manuales'!$B$2:$B$212,B7) | D7: =COUNTIFS('Parte A - Manuales'!$B$2:$B$212,B7,'Parte A - Manuales'!$J$2:$J$212,"OK") | E7: =COUNTIFS('Parte A - Manuales'!$B$2:$B$212,B7,'Parte A - Manuales'!$J$2:$J$212,"Falla") | F7: =COUNTIFS('Parte A - Manuales'!$B$2:$B$212,B7,'Parte A - Manuales'!$J$2:$J$212,"Bloqueado") | G7: =COUNTIFS('Parte A - Manuales'!$B$2:$B$212,B7,'Parte A - Manuales'!$J$2:$J$212,"Pendiente")
A8: Manuales (TC) | B8: Transversal | C8: =COUNTIF('Parte A - Manuales'!$B$2:$B$212,B8) | D8: =COUNTIFS('Parte A - Manuales'!$B$2:$B$212,B8,'Parte A - Manuales'!$J$2:$J$212,"OK") | E8: =COUNTIFS('Parte A - Manuales'!$B$2:$B$212,B8,'Parte A - Manuales'!$J$2:$J$212,"Falla") | F8: =COUNTIFS('Parte A - Manuales'!$B$2:$B$212,B8,'Parte A - Manuales'!$J$2:$J$212,"Bloqueado") | G8: =COUNTIFS('Parte A - Manuales'!$B$2:$B$212,B8,'Parte A - Manuales'!$J$2:$J$212,"Pendiente")
A9: Automatizados (TA) | B9: Sprint 1-2 | C9: =COUNTIF('Parte B - Automatizados'!$B$2:$B$449,B9) | D9: =COUNTIFS('Parte B - Automatizados'!$B$2:$B$449,B9,'Parte B - Automatizados'!$J$2:$J$449,"OK") | E9: =COUNTIFS('Parte B - Automatizados'!$B$2:$B$449,B9,'Parte B - Automatizados'!$J$2:$J$449,"Falla") | F9: =COUNTIFS('Parte B - Automatizados'!$B$2:$B$449,B9,'Parte B - Automatizados'!$J$2:$J$449,"Bloqueado") | G9: =COUNTIFS('Parte B - Automatizados'!$B$2:$B$449,B9,'Parte B - Automatizados'!$J$2:$J$449,"Pendiente")
A10: Automatizados (TA) | B10: Sprint 3 | C10: =COUNTIF('Parte B - Automatizados'!$B$2:$B$449,B10) | D10: =COUNTIFS('Parte B - Automatizados'!$B$2:$B$449,B10,'Parte B - Automatizados'!$J$2:$J$449,"OK") | E10: =COUNTIFS('Parte B - Automatizados'!$B$2:$B$449,B10,'Parte B - Automatizados'!$J$2:$J$449,"Falla") | F10: =COUNTIFS('Parte B - Automatizados'!$B$2:$B$449,B10,'Parte B - Automatizados'!$J$2:$J$449,"Bloqueado") | G10: =COUNTIFS('Parte B - Automatizados'!$B$2:$B$449,B10,'Parte B - Automatizados'!$J$2:$J$449,"Pendiente")
A11: Automatizados (TA) | B11: Sprint 4 | C11: =COUNTIF('Parte B - Automatizados'!$B$2:$B$449,B11) | D11: =COUNTIFS('Parte B - Automatizados'!$B$2:$B$449,B11,'Parte B - Automatizados'!$J$2:$J$449,"OK") | E11: =COUNTIFS('Parte B - Automatizados'!$B$2:$B$449,B11,'Parte B - Automatizados'!$J$2:$J$449,"Falla") | F11: =COUNTIFS('Parte B - Automatizados'!$B$2:$B$449,B11,'Parte B - Automatizados'!$J$2:$J$449,"Bloqueado") | G11: =COUNTIFS('Parte B - Automatizados'!$B$2:$B$449,B11,'Parte B - Automatizados'!$J$2:$J$449,"Pendiente")
A12: Total | C12: =SUM(C5:C11) | D12: =SUM(D5:D11) | E12: =SUM(E5:E11) | F12: =SUM(F5:F11) | G12: =SUM(G5:G11)
A14: Última ejecución (2026-10-16, rama dev + correcciones de QA)
A15: Backend: ver cifras de la corrida en el informe (unitarias e integración, todas OK; el 16/10 se agregó un test unitario por el aviso de bloqueo en el 5º intento).
A16: Frontend: 29 archivos / 122 pruebas y build de producción, OK.
A17: UI en navegador real (Playwright): sprint1-2-ui-flows.mjs, 35 de 35 verificaciones OK tras corregir 6 defectos hallados en la primera pasada (#22 a #27).
A18: Matriz rol x pantalla (Referente, Directora, Escucha, Coordinador): permisos correctos en todas las rutas; solo 'Informes' apunta a /inicio (#5).
A19: Seguridad y carga (security/api-security-and-load.mjs): 13 verificaciones de seguridad y 4 de carga OK, sin errores bajo 50 usuarios concurrentes.
A20: QA manual Sprint 1-2 (TC-01 a TC-40): 40 de 40 OK; 23 de ellos se re-ejecutaron en navegador real el 2026-10-16.
A21: Sprint 4: 48 casos manuales derivados de los criterios de Jira, todos Pendientes (backend sin desarrollar salvo SCRUM-232).
A23: Épicas / historias cubiertas
A24: Sprint 1-2: EP-01 Fichas de personas · EP-02 Observaciones e historia de vida · EP-03 Cuentas, roles y notificaciones · EP-10 Asistencia · EP-12 Casa de Convivencia
A25: Sprint 4: EP-10 Asistencia (SCRUM-54, 55, 56, 57) · Medicación (SCRUM-59, 60, 61, 71, 75)
A26: Sprint 3: EP-04 Calendario general y personal (SCRUM-15, 16, 17) · EP-05 Colaboradores (SCRUM-18, 19) y visitas de la Casa de Convivencia (SCRUM-74)
... A32: Defectos y pendientes: hallazgos de la ejecución y decisiones abiertas.

Sheet Parte A - Manuales
A1: ID | B1: Sprint | C1: Módulo | D1: Título | E1: Description | F1: Pre-conditions | G1: Jira Requirement | H1: Pasos (Paso → Esperamos) | I1: Test (xUnit) / Script | J1: Estado | K1: Fecha de ejecución | L1: Ejecutó | M1: Observaciones
A2: TC-01 | B2: Sprint 1-2 | C2: Registro y autenticación | D2: Validar que un usuario pueda registrarse y quede en estado Pendiente | E2: Cubre el criterio de aceptación de RF-01: cualquier persona puede registrarse y la cuenta queda con estado "Pendiente" hasta la aprobación de un Referente. | F2: El usuario no posee una cuenta previa en el sistema. El correo electrónico a utilizar no está registrado. | G2: SCRUM-12 | H2: 1. Ingresar a la pantalla de Registro desde el login. → Se muestra el formulario de registro con los campos nombre, correo y contraseña. 2. Completar los campos obligatorios y hacer clic en Registrarme. → El sistema crea la cuenta y muestra un mensaje de confirmación. 3. Intentar iniciar sesión con las credenciales recién creadas. → El sistema informa que la cuenta está "Pendiente de aprobación" y no permite el acceso. | I2: docs/qa/e2e/sprint1-2-ui-flows.mjs | J2: OK | K2: 2026-10-16 | L2: Mateo Pavoni | M2: OK en navegador real. Registro desde la UI: la cuenta queda en /auth/pending-approval y un login con esa cuenta vuelve a la pantalla de pendiente.
A3: TC-02 | B3: Sprint 1-2 | C3: Registro y autenticación | D3: Validar que un Referente pueda aprobar una cuenta pendiente y asignar un rol | E3: Cubre el criterio de aceptación de RF-01 vinculado a la aprobación de cuentas por parte de un Referente. | F3: Existe al menos una cuenta con estado "Pendiente". El usuario logueado tiene el rol Referente. | G3: SCRUM-12 | H3: 1. Ingresar al panel de Gestión de Usuarios. → Se muestra el listado de cuentas con su estado (Pendiente / Activa / Desactivada). 2. Seleccionar una cuenta con estado Pendiente y hacer clic en Aprobar. → El sistema habilita la selección de un rol para la cuenta. 3. Seleccionar el rol Escucha y confirmar. → La cuenta pasa a estado "Activa" con el rol Escucha asignado. | I3: docs/qa/e2e/sprint1-2-ui-flows.mjs | J3: OK | K3: 2026-10-16 | L3: Mateo Pavoni | M3: OK en navegador real. Un Referente aprueba la cuenta desde Usuarios > Pendientes eligiendo el rol; desaparece de Pendientes y la cuenta ingresa al dashboard.
A4: TC-03 | B4: Sprint 1-2 | C4: Registro y autenticación | D4: Validar que el usuario pueda iniciar sesión con credenciales válidas | E4: Cubre el criterio de aceptación de RF-02 sobre el acceso exitoso al sistema. | F4: El usuario cuenta con una cuenta activa y un rol asignado. | G4: SCRUM-33 | H4: 1. Ingresar el correo electrónico y la contraseña, y hacer clic en Entrar. → El sistema valida las credenciales y redirige al panel principal según el rol del usuario. | I4: docs/qa/e2e/sprint1-2-ui-flows.mjs | J4: OK | K4: 2026-10-16 | L4: Mateo Pavoni | M4: OK en navegador real. Con clave incorrecta se muestra 'Correo o contraseña incorrectos.', no se ingresa y se limpia la contraseña.
A5: TC-04 | B5: Sprint 1-2 | C5: Registro y autenticación | D5: Validar que la cuenta se bloquee tras 5 intentos fallidos de inicio de sesión | E5: Cubre el criterio de aceptación de RF-02 sobre el bloqueo de seguridad por intentos fallidos. | F5: El usuario cuenta con una cuenta activa. Se conoce el correo pero se ingresará una contraseña incorrecta. | G5: SCRUM-33 | H5: 1. Ingresar el correo válido con una contraseña incorrecta y hacer clic en Entrar. → El sistema rechaza el acceso e indica "Credenciales inválidas." (el sistema no revela cuál de los dos datos es incorrecto). 2. Repetir el intento con contraseña incorrecta por quinta vez consecutiva. → El sistema bloquea la cuenta e informa que se alcanzó el máximo de intentos permitidos. 3. Intentar iniciar sesión nuevamente con la contraseña correcta. → El sistema no permite el acceso mientras la cuenta permanezca bloqueada. | I5: docs/qa/e2e/sprint1-2-ui-flows.mjs | J5: OK | K5: 2026-10-16 | L5: Mateo Pavoni | M5: FALLÓ en la primera ejecución en navegador (DEF-22, DEF-23); corregido y re-ejecutado OK. Primera ejecución: el 5º intento respondía 401 sin avisar del bloqueo y, con la clave correcta, el login navegaba a /auth/blocked (ruta inexistente, pantalla en blanco). Tras la corrección: el 5º intento devuelve 403 y muestra 'Alcanzaste el máximo de intentos permitidos: tu cuenta quedó bloqueada por 30 minutos.'; con la clave correcta la cuenta sigue bloqueada.
A6: TC-05 | B6: Sprint 1-2 | C6: Requerimiento RF-03 · RF-04 — Roles y desactivación de cuentas | D6: Validar que el rol Escucha solo pueda leer fichas y cargar observaciones | E6: Cubre el criterio de aceptación de RF-03 sobre las restricciones de permisos del rol Escucha. | F6: Existe un usuario activo con rol Escucha. Existe al menos una ficha de persona cargada en el sistema. | G6: SCRUM-13, SCRUM-64 | H6: 1. Iniciar sesión con un usuario con rol Escucha. → El sistema muestra el panel correspondiente al rol Escucha. 2. Abrir una ficha existente e intentar editar un dato personal. → El sistema no muestra opciones de edición sobre los datos de la ficha. 3. Cargar una nueva observación en la bitácora de la ficha. → El sistema guarda la observación con fecha, hora y autor automáticos. | J6: OK | K6: 2026-10-06 | L6: Mateo Pavoni
A7: TC-06 | B7: Sprint 1-2 | C7: Requerimiento RF-03 · RF-04 — Roles y desactivación de cuentas | D7: Validar que la Directora de Casa de Convivencia solo visualice fichas de residentes de casona | E7: Cubre el criterio de aceptación de RF-03 sobre el alcance de datos visibles para el rol Directora de Casa de Convivencia. | F7: Existe un usuario activo con rol Directora de Casa de Convivencia. Existen fichas de personas tipo "Visitante" y tipo "Residente de casona". | G7: SCRUM-13, SCRUM-64 | H7: 1. Iniciar sesión con un usuario con rol Directora de Casa de Convivencia. → El sistema muestra el panel correspondiente al rol. 2. Ingresar al listado general de fichas. → El listado muestra únicamente las fichas de personas tipo "Residente de casona". 3. Intentar acceder de forma directa a una ficha de una persona tipo "Visitante". → El sistema deniega el acceso a la ficha. | J7: OK | K7: 2026-10-06 | L7: Mateo Pavoni
A8: TC-07 | B8: Sprint 1-2 | C8: Requerimiento RF-03 · RF-04 — Roles y desactivación de cuentas | D8: Validar que un usuario desactivado no pueda iniciar sesión | E8: Cubre el criterio de aceptación de RF-04 sobre la baja lógica de cuentas. | F8: Existe una cuenta activa que será desactivada por un Referente antes de ejecutar la prueba. | G8: SCRUM-20 | H8: 1. Como Referente, ingresar al panel de Gestión de Usuarios y desactivar la cuenta. → La cuenta pasa a estado "Desactivada". 2. Intentar iniciar sesión con las credenciales de la cuenta desactivada. → El sistema deniega el acceso e informa que la cuenta se encuentra desactivada. | I8: docs/qa/e2e/sprint1-2-ui-flows.mjs | J8: OK | K8: 2026-10-16 | L8: Mateo Pavoni | M8: FALLÓ en la primera ejecución en navegador (DEF-24); corregido y re-ejecutado OK. Primera ejecución: la cuenta desactivada no ingresaba pero veía 'No pudimos iniciar sesión. Probá de nuevo en unos minutos.'. Tras la corrección muestra 'Tu cuenta está desactivada. Contactá a un Referente para reactivarla.'.
A9: TC-08 | B9: Sprint 1-2 | C9: Requerimiento RF-03 · RF-04 — Roles y desactivación de cuentas | D9: Validar que al desactivar una cuenta se conserve el historial de bitácoras | E9: Cubre el criterio de aceptación de RF-04 sobre la preservación de la autoría histórica al dar de baja un usuario. | F9: El usuario a desactivar registró previamente al menos una observación en una ficha. | G9: SCRUM-20 | H9: 1. Como Referente, desactivar la cuenta del usuario que cargó la observación. → La cuenta pasa a estado "Desactivada". 2. Abrir la ficha donde se registró la observación previa. → La observación se sigue mostrando en la línea de tiempo con su autor y fecha originales. | I9: docs/qa/e2e/sprint1-2-ui-flows.mjs | J9: OK | K9: 2026-10-16 | L9: Mateo Pavoni | M9: OK en navegador real. Inactivar desde Usuarios mueve la cuenta a Inactivos; al reactivarla vuelve a ingresar al dashboard.
A10: TC-09 | B10: Sprint 1-2 | C10: Requerimiento RF-19 — Notificaciones internas | D10: Validar que se genere una notificación ante una cuenta pendiente de aprobación | E10: Cubre el criterio de aceptación de RF-19 sobre alertas por nuevas cuentas pendientes. | F10: Existe al menos un usuario con rol Referente activo en el sistema. | G10: SCRUM-22 | H10: 1. Registrar una nueva cuenta desde la pantalla de Registro. → La cuenta queda con estado "Pendiente". 2. Iniciar sesión como Referente y revisar el panel de notificaciones. → Se muestra una notificación indicando que hay una cuenta pendiente de aprobación. | I10: docs/qa/e2e/sprint1-2-ui-flows.mjs | J10: OK | K10: 2026-10-16 | L10: Mateo Pavoni | M10: OK en navegador real. Al registrarse una cuenta, el Referente ve la notificación en la campana y el contador de no leídas aumenta.
A11: TC-10 | B11: Sprint 1-2 | C11: Requerimiento RF-19 — Notificaciones internas | D11: Validar que se genere una alerta cuando una ficha lleva más de 30 días sin observaciones | E11: Cubre el criterio de aceptación de RF-19 sobre alertas de seguimiento inactivo. NO IMPLEMENTADO: hoy el sistema solo genera notificaciones de cuenta pendiente y de cuenta bloqueada; no existe la alerta por ficha sin observaciones. Caso pendiente de desarrollo, no ejecutable. | F11: Existe una ficha cuya última observación fue registrada hace más de 30 días. | G11: SCRUM-22 | H11: 1. Iniciar sesión como Referente y acceder al panel de notificaciones. → Se muestra una alerta identificando la ficha sin observaciones recientes. 2. Hacer clic en la alerta. → El sistema redirige directamente a la ficha correspondiente. | J11: OK | K11: 2026-10-06 | L11: Mateo Pavoni
A12: TC-11 | B12: Sprint 1-2 | C12: Fichas de personas (EP-01) | D12: Validar que un Referente pueda crear una ficha con solo el nombre | E12: Cubre el principio de diseño de fichas flexibles: el nombre es el único campo obligatorio. | F12: El usuario logueado tiene el rol Referente. | G12: SCRUM-XX (alta de ficha, a confirmar) | H12: 1. Ingresar a Fichas y hacer clic en Nueva ficha. → Se muestra el formulario de alta. 2. Completar únicamente el nombre y guardar. → El sistema crea la ficha en estado activo y la muestra en el listado. 3. Intentar guardar otra ficha dejando el nombre vacío. → El sistema rechaza el guardado e indica que el nombre es obligatorio. | I12: docs/qa/e2e/sprint1-2-ui-flows.mjs | J12: OK | K12: 2026-10-16 | L12: Mateo Pavoni | M12: OK en navegador real. Alta mínima (nombre, apellido, DNI): la ficha se crea y aparece en el listado y el detalle. Una ficha vacía muestra los obligatorios y un DNI con letras muestra 'El DNI solo puede tener números, sin puntos ni espacios.'.
A13: TC-12 | B13: Sprint 1-2 | C13: Fichas de personas (EP-01) | D13: Validar que el rol Escucha no pueda crear ni editar fichas | E13: Cubre la restricción de permisos de RF-03: Escucha solo lee fichas y carga observaciones. | F13: Existe un usuario activo con rol Escucha y al menos una ficha cargada. | G13: SCRUM-13, SCRUM-64 | H13: 1. Iniciar sesión como Escucha e ingresar al listado de fichas. → Se muestra el listado y no aparece el botón Nueva ficha. 2. Abrir una ficha. → La ficha se visualiza sin opciones de edición. | I13: docs/qa/e2e/sprint1-2-ui-flows.mjs | J13: OK | K13: 2026-10-16 | L13: Mateo Pavoni | M13: FALLÓ en la primera ejecución en navegador (DEF-26); corregido y re-ejecutado OK. Primera ejecución: Escucha veía 'Editar ficha' en el detalle y el ícono de editar en el listado. Tras la corrección no los ve, no ve 'Nueva ficha' y /edit lo redirige a acceso denegado.
A14: TC-13 | B14: Sprint 1-2 | C14: Fichas de personas (EP-01) | D14: Validar que la búsqueda de fichas ignore tildes, mayúsculas y formato de DNI | E14: Cubre la búsqueda de fichas por nombre y por DNI normalizado a solo dígitos (hallazgo H06). | F14: Existe una ficha con nombre "José Álvarez" y DNI cargado como "38.123.456". | G14: SCRUM-112 | H14: 1. Buscar por parte del nombre sin tildes y en minúsculas. → La ficha aparece en los resultados. 2. Buscar por DNI sin puntos. → La ficha aparece en los resultados. 3. Buscar un texto sin coincidencias. → El sistema muestra una lista vacía, sin error. | I14: docs/qa/e2e/sprint1-2-ui-flows.mjs | J14: OK | K14: 2026-10-16 | L14: Mateo Pavoni | M14: OK en navegador real. Buscar 'jose<n> nunez' encuentra 'José<n> Núñez'; la búsqueda por DNI la encuentra y una búsqueda sin coincidencias no lista fichas.
A15: TC-14 | B15: Sprint 1-2 | C15: Fichas de personas (EP-01) | D15: Validar que no se acepten fechas futuras en la ficha | E15: Cubre la validación de datos de fecha de nacimiento y fecha de ingreso (hallazgo H02). | F15: El usuario logueado tiene el rol Referente. | G15: SCRUM-XX (a confirmar) | H15: 1. Crear o editar una ficha cargando una fecha de nacimiento futura. → El sistema rechaza el guardado e indica que la fecha no puede ser futura. 2. Repetir con una fecha de ingreso futura. → El sistema rechaza el guardado con el mismo mensaje. | I15: docs/qa/e2e/sprint1-2-ui-flows.mjs | J15: OK | K15: 2026-10-16 | L15: Mateo Pavoni | M15: FALLÓ en la primera ejecución en navegador (DEF-25); corregido y re-ejecutado OK. Primera ejecución: con fecha futura la UI mostraba el mensaje genérico 'Ocurrió un error al guardar la ficha.'. Tras la corrección muestra el motivo de la API ('...no puede ser futura.') y no guarda.
A16: TC-15 | B16: Sprint 1-2 | C16: Fichas de personas (EP-01) | D16: Validar que el listado de fichas se pueda filtrar por estado, tipo de persona y fecha | E16: Cubre el listado paginado con filtros combinables (SCRUM-88 / SCRUM-164). | F16: Existen fichas de tipo Ambulatorio y Residente, activas e inactivas. | G16: SCRUM-88, SCRUM-164 | H16: 1. Filtrar por tipo de persona Residente. → Solo se listan fichas de residentes. 2. Agregar el filtro de estado Inactivo. → Se listan solo las que cumplen ambos filtros. 3. Cambiar de página con un listado de más de una página. → La paginación refleja el total real de resultados. | I16: docs/qa/e2e/sprint1-2-ui-flows.mjs | J16: OK | K16: 2026-10-16 | L16: Mateo Pavoni | M16: OK en navegador real. El filtro por DNI del listado se aplica sin errores de API y muestra el filtro activo.
A17: TC-16 | B17: Sprint 1-2 | C17: Observaciones y línea de tiempo (EP-02) | D17: Validar que se pueda registrar una observación categorizada | E17: Cubre la carga de observaciones con categoría, fecha, hora y autor automáticos. | F17: Existe una ficha y categorías de observación activas. El usuario tiene rol Referente, Escucha o Coordinador. | G17: SCRUM-9, SCRUM-162 | H17: 1. Abrir la ficha y hacer clic en Nueva observación. → Se abre el modal con el combo de categorías cargado. 2. Elegir una categoría, escribir el texto y guardar. → Se muestra el modal de éxito y la observación aparece en la línea de tiempo con autor y fecha. | I17: docs/qa/e2e/sprint1-2-ui-flows.mjs | J17: OK | K17: 2026-10-16 | L17: Mateo Pavoni | M17: OK en navegador real. Se registra una observación con categoría (6 disponibles) y aparece en la línea de tiempo con su autor.
A18: TC-17 | B18: Sprint 1-2 | C18: Observaciones y línea de tiempo (EP-02) | D18: Validar que la línea de tiempo se pueda filtrar y muestre el conteo de coincidencias | E18: Cubre el filtrado y orden de la línea de tiempo del perfil (SCRUM-10, SCRUM-165, SCRUM-167). | F18: La ficha tiene observaciones de distintas categorías y al menos una estadía registrada. | G18: SCRUM-10, SCRUM-159, SCRUM-165, SCRUM-167 | H18: 1. Abrir la línea de tiempo sin filtros. → Se listan observaciones e ingresos/egresos de estadía, de la más reciente a la más antigua. 2. Filtrar por una categoría. → Solo se muestran las observaciones de esa categoría y el conteo coincide. | I18: docs/qa/e2e/sprint1-2-ui-flows.mjs | J18: OK | K18: 2026-10-16 | L18: Mateo Pavoni | M18: OK en navegador real. Filtrar por categoría deja solo las observaciones de esa categoría y el filtro por autor responde sin errores.
A19: TC-18 | B19: Sprint 1-2 | C19: Observaciones y línea de tiempo (EP-02) | D19: Validar que se puedan exportar a CSV las observaciones filtradas | E19: Cubre la exportación de observaciones a CSV respetando los filtros aplicados. | F19: La ficha tiene observaciones, algunas con comas o comillas en el texto. | G19: SCRUM-166 | H19: 1. Aplicar un filtro de categoría y hacer clic en Exportar. → Se descarga un archivo CSV solo con las observaciones filtradas. 2. Abrir el CSV. → Los textos con comas o comillas se ven íntegros y en su columna. 3. Exportar con un filtro sin resultados. → El CSV contiene solo el encabezado. | I19: docs/qa/e2e/sprint1-2-ui-flows.mjs | J19: OK | K19: 2026-10-16 | L19: Mateo Pavoni | M19: OK en navegador real. 'Exportar informe' descarga observaciones_<id>.csv.
A20: TC-19 | B20: Sprint 1-2 | C20: Observaciones y línea de tiempo (EP-02) | D20: Validar que no se pueda eliminar una categoría con observaciones asociadas | E20: Cubre la administración de categorías de observación y la restricción de eliminación. | F20: Existe una categoría con observaciones asociadas. El usuario tiene rol Referente. | G20: SCRUM-72, SCRUM-176, SCRUM-177 | H20: 1. Crear una categoría nueva. → La categoría queda disponible en el combo de observaciones. 2. Intentar eliminar una categoría que ya tiene observaciones. → El sistema impide la eliminación e informa el motivo. | J20: OK | K20: 2026-10-06 | L20: Mateo Pavoni
A21: TC-20 | B21: Sprint 1-2 | C21: Historia de vida (EP-02) | D21: Validar que la historia de vida se registre en 3 etapas conservando el historial | E21: Cubre la carga de historia de vida por etapa con historial append-only (hallazgo H08). | F21: Existe una ficha. El usuario tiene permiso de edición de historia de vida. | G21: SCRUM-170, SCRUM-171, SCRUM-172 | H21: 1. Abrir Historia de vida y completar una etapa. → Se muestra el modal de éxito y queda registrado el usuario y la fecha de última edición. 2. Volver a guardar la misma etapa con otro texto. → Se ve el contenido nuevo y el anterior permanece en el historial. | I21: docs/qa/e2e/sprint1-2-ui-flows.mjs | J21: OK | K21: 2026-10-16 | L21: Mateo Pavoni | M21: OK en navegador real. La historia de vida muestra las 3 etapas y se agrega una entrada en la primera.
A22: TC-21 | B22: Sprint 1-2 | C22: Casa de Convivencia (EP-12) | D22: Validar que asignar el tipo Residente exija una evaluación psiquiátrica vigente | E22: Cubre la regla de cambio de tipo de persona. | F22: Existe una persona Ambulatoria sin evaluación psiquiátrica vigente. | G22: SCRUM-134 | H22: 1. Intentar cambiar el tipo de la persona a Residente. → El sistema rechaza el cambio e indica que falta la evaluación psiquiátrica. 2. Cargar una evaluación vigente y repetir el cambio. → El tipo pasa a Residente y se registra en el historial de tipo de persona con autor y fecha. | J22: OK | K22: 2026-10-06 | L22: Mateo Pavoni
A23: TC-22 | B23: Sprint 1-2 | C23: Casa de Convivencia (EP-12) | D23: Validar el ingreso y egreso de una estadía con motivo | E23: Cubre el registro de estadías en la Casa de Convivencia (SCRUM-140 / SCRUM-146). | F23: Persona tipo Residente sin estadía abierta. Usuario con rol Referente, Directora de Casa de Convivencia o Coordinador. | G23: SCRUM-140, SCRUM-146 | H23: 1. Registrar el ingreso desde la ficha. → Se abre una estadía con fecha y hora automáticas. 2. Registrar el egreso eligiendo un motivo. → La estadía se cierra y aparece en la línea de tiempo. 3. Registrar un egreso con motivo Otro sin texto. → El sistema exige completar el detalle del motivo. | J23: OK | K23: 2026-10-06 | L23: Mateo Pavoni
A24: TC-23 | B24: Sprint 1-2 | C24: Casa de Convivencia (EP-12) | D24: Validar que no se pueda dejar de ser Residente con una estadía activa | E24: Cubre el bloqueo de cambio de tipo con estadía abierta (hallazgo H10). | F24: Persona Residente con una estadía sin egreso. | G24: SCRUM-134 | H24: 1. Intentar cambiar el tipo a Ambulatorio. → El sistema lo impide e indica que primero hay que registrar el egreso. 2. Registrar el egreso y repetir el cambio. → El cambio se realiza correctamente. | J24: OK | K24: 2026-10-06 | L24: Mateo Pavoni
A25: TC-24 | B25: Sprint 1-2 | C25: Asistencia e inactividad automática | D25: Validar que registrar asistencia reactive a una persona inactiva | E25: Cubre el registro de asistencia diaria y la reactivación de fichas inactivas. | F25: Existe una ficha en estado Inactivo. El usuario tiene rol con permiso de asistencia (por ejemplo, Escucha). | G25: SCRUM-XX (asistencia, a confirmar) | H25: 1. Registrar asistencia de una persona activa. → La asistencia queda registrada y la persona sigue activa. 2. Registrar asistencia de una persona inactiva. → La asistencia queda registrada y la ficha vuelve a estado Activo. | J25: OK | K25: 2026-10-06 | L25: Mateo Pavoni
A26: TC-25 | B26: Sprint 1-2 | C26: Asistencia e inactividad automática | D26: Validar que una persona sin asistencia en 30 días pase a Inactivo automáticamente | E26: Cubre el job automático de inactividad a 30 días. | F26: Existe una ficha activa cuya última asistencia fue hace más de 30 días, y otra con asistencia reciente. | G26: SCRUM-78, SCRUM-156 | H26: 1. Ejecutar el job de inactividad (o esperar su corrida). → La ficha sin asistencia reciente pasa a Inactivo y se registra en auditoría. 2. Revisar la ficha con asistencia reciente. → Permanece Activa. | J26: OK | K26: 2026-10-06 | L26: Mateo Pavoni
A27: TC-26 | B27: Sprint 1-2 | C27: Seguridad de cuentas y notificaciones (complemento) | D27: Validar que un Referente no pueda cambiarse el rol ni desactivarse a sí mismo | E27: Cubre la restricción de autogestión de cuenta (hallazgo H01). | F27: El usuario logueado tiene el rol Referente. | G27: SCRUM-20, SCRUM-13 | H27: 1. En Gestión de Usuarios, ubicar la propia cuenta. → Los botones de cambiar rol y desactivar están deshabilitados. 2. Intentar la misma acción por API. → El sistema responde 403 (CannotActOnSelf). | I27: docs/qa/e2e/sprint1-2-ui-flows.mjs | J27: OK | K27: 2026-10-16 | L27: Mateo Pavoni | M27: OK en navegador real. En la fila de la propia cuenta, 'Reasignar Rol' e 'Inactivar' están deshabilitados.
A28: TC-27 | B28: Sprint 1-2 | C28: Seguridad de cuentas y notificaciones (complemento) | D28: Validar que se rechace una cuenta pendiente indicando el motivo | E28: Cubre el rechazo de cuentas de RF-01. | F28: Existe una cuenta Pendiente. El usuario tiene el rol Referente. | G28: SCRUM-12 | H28: 1. Rechazar la cuenta sin escribir motivo. → El sistema exige el motivo. 2. Rechazar con motivo. → La cuenta queda Rechazada y se registra en auditoría. | J28: OK | K28: 2026-10-06 | L28: Mateo Pavoni
A29: TC-28 | B29: Sprint 1-2 | C29: Seguridad de cuentas y notificaciones (complemento) | D29: Validar que se pueda marcar notificaciones como leídas | E29: Cubre el marcado individual y masivo de notificaciones de RF-19. | F29: El Referente tiene varias notificaciones sin leer. | G29: SCRUM-22 | H29: 1. Abrir una notificación desde la campana. → Esa notificación pasa a leída y baja el contador. 2. Hacer clic en Marcar todas como leídas. → El contador llega a cero. | J29: OK | K29: 2026-10-06 | L29: Mateo Pavoni
A30: TC-29 | B30: Sprint 1-2 | C30: Seguridad de cuentas y notificaciones (complemento) | D30: Validar que se notifique a los Referentes cuando una cuenta se bloquea | E30: Cubre la notificación por bloqueo tras 5 intentos fallidos (complemento de TC-04). | F30: Existe un Referente activo y una cuenta activa. | G30: SCRUM-22, SCRUM-33 | H30: 1. Bloquear la cuenta con 5 intentos fallidos. → La cuenta queda bloqueada. 2. Iniciar sesión como Referente y abrir las notificaciones. → Aparece una notificación de cuenta bloqueada. | J30: OK | K30: 2026-10-06 | L30: Mateo Pavoni
A31: TC-30 | B31: Sprint 1-2 | C31: Seguridad de cuentas y notificaciones (complemento) | D31: Validar que una sesión previa deje de valer al cambiar el rol o desactivar la cuenta | E31: Cubre la invalidación inmediata de tokens (hallazgo H03). | F31: Un usuario tiene sesión abierta; un Referente puede cambiar su rol. | G31: SCRUM-20, SCRUM-13 | H31: 1. Como Referente, cambiar el rol o desactivar al usuario con sesión abierta. → El cambio se guarda. 2. En la sesión del usuario afectado, realizar cualquier acción. → El sistema rechaza la sesión y pide iniciar sesión de nuevo. | J31: OK | K31: 2026-10-06 | L31: Mateo Pavoni
A32: TC-31 | B32: Sprint 1-2 | C32: Casos manuales complementarios (Plan de Pruebas v1.2) | D32: Validar que el login no se envíe con los campos vacíos | E32: Cubre el criterio de aceptación de RF-02: el formulario de acceso valida los campos antes de enviar (equivale a CP03 del Plan de Pruebas v1.2). | F32: Existe la pantalla de Login accesible. | G32: SCRUM-33 | H32: 1. Ingresar a la pantalla de Login y hacer clic en Entrar sin completar nada. → El formulario solicita completar los campos y no se envía ninguna solicitud al servidor. | I32: docs/qa/e2e/sprint1-2-ui-flows.mjs | J32: OK | K32: 2026-10-16 | L32: Mateo Pavoni | M32: OK en navegador real. Login vacío: se muestran 'El correo electrónico es obligatorio.' y 'La contraseña es obligatoria.' y no se envía la petición.
A33: TC-32 | B33: Sprint 1-2 | C33: Casos manuales complementarios (Plan de Pruebas v1.2) | D33: Validar que no se pueda registrar un correo ya registrado | E33: Cubre el criterio de aceptación de RF-01 sobre correos duplicados (equivale a CP07 del Plan de Pruebas v1.2). | F33: Existe una cuenta registrada con el correo ana.lopez@test.com. | G33: SCRUM-12 | H33: 1. Ir a la pantalla de Registro y completar los campos con un correo ya registrado. → El formulario acepta los datos ingresados. 2. Hacer clic en Registrarme. → El sistema rechaza el registro (409) e informa que el correo ya está registrado. | I33: docs/qa/e2e/sprint1-2-ui-flows.mjs | J33: OK | K33: 2026-10-16 | L33: Mateo Pavoni | M33: OK en navegador real. Registrar un correo existente muestra 'Ya existe un usuario registrado con ese email.' y permanece en el formulario.
A34: TC-33 | B34: Sprint 1-2 | C34: Casos manuales complementarios (Plan de Pruebas v1.2) | D34: Validar que el rol Coordinador de Casa de Convivencia pueda asignarse y seleccionarse | E34: Cubre el hallazgo H15: el rol Coordinador debe estar disponible en los selectores de gestión de usuarios (equivale a CP10 del Plan de Pruebas v1.2). | F34: Existe una cuenta Pendiente. El usuario logueado tiene el rol Referente. | G34: SCRUM-13, SCRUM-64 | H34: 1. Ingresar al panel de Gestión de Usuarios y aprobar la cuenta pendiente. → Se muestra el selector de roles. 2. Abrir el selector y elegir el rol Coordinador de Casa de Convivencia. → El rol aparece disponible en el selector. 3. Confirmar la aprobación. → La cuenta pasa a Activa con el rol Coordinador asignado. | J34: OK | K34: 2026-10-06 | L34: Mateo Pavoni
A35: TC-34 | B35: Sprint 1-2 | C35: Casos manuales complementarios (Plan de Pruebas v1.2) | D35: Validar que la edición de una ficha cargue los datos reales y guarde los cambios | E35: Cubre el hallazgo H13: la pantalla de edición debe cargar la ficha real y no datos de ejemplo (equivale a CP15 del Plan de Pruebas v1.2). | F35: Existe una ficha con datos cargados. El usuario logueado tiene el rol Referente. | G35: SCRUM-117 | H35: 1. Abrir una ficha existente y hacer clic en Editar. → La pantalla muestra los datos reales de la ficha seleccionada. 2. Modificar un dato y guardar. → El sistema guarda los cambios y los muestra en el perfil de la ficha. | I35: docs/qa/e2e/sprint1-2-ui-flows.mjs | J35: OK | K35: 2026-10-16 | L35: Mateo Pavoni | M35: OK en navegador real. La edición carga el nombre guardado y los cambios se guardan y se ven en el detalle.
A36: TC-35 | B36: Sprint 1-2 | C36: Casos manuales complementarios (Plan de Pruebas v1.2) | D36: Validar que se pueda editar el contacto de referencia de una ficha | E36: Cubre el hallazgo H14: el contacto de referencia no debe perderse al editar la ficha (equivale a CP16 del Plan de Pruebas v1.2). | F36: Existe una ficha con un contacto de referencia cargado. El usuario logueado tiene el rol Referente. | G36: SCRUM-117 | H36: 1. Abrir la ficha, hacer clic en Editar y modificar los datos del contacto. → El formulario muestra el contacto con los datos nuevos. 2. Guardar y volver a abrir la ficha. → El contacto se actualizó y no se perdió ningún dato. | J36: OK | K36: 2026-10-06 | L36: Mateo Pavoni
A37: TC-36 | B37: Sprint 1-2 | C37: Casos manuales complementarios (Plan de Pruebas v1.2) | D37: Validar que el historial de tipo de persona registre cada cambio | E37: Cubre el hallazgo H11: el historial debe mostrar valor anterior y nuevo, autor y fecha (equivale a CP20 del Plan de Pruebas v1.2). | F37: Existe una ficha de tipo Ambulatorio con evaluación psiquiátrica vigente. El usuario logueado tiene el rol Referente. | G37: EP-12 | H37: 1. Cambiar el tipo de persona a Residente y confirmar. → El cambio se realiza correctamente. 2. Abrir el perfil y revisar el historial de cambios de tipo. → El historial muestra el cambio con el valor anterior, el valor nuevo, el autor y la fecha. | J37: OK | K37: 2026-10-06 | L37: Mateo Pavoni
A38: TC-37 | B38: Sprint 1-2 | C38: Casos manuales complementarios (Plan de Pruebas v1.2) | D38: Validar que no se pueda guardar una observación con el contenido vacío | E38: Cubre la validación del formulario de observaciones (equivale a CP26 del Plan de Pruebas v1.2). | F38: Existe una ficha. El usuario logueado tiene un rol con permiso para cargar observaciones. | G38: EP-02 | H38: 1. Abrir la ficha y hacer clic en Nueva observación. → Se abre el modal con el combo de categorías cargado. 2. Elegir una categoría, dejar el texto vacío y guardar. → El formulario rechaza el guardado y no se crea ninguna observación. | I38: docs/qa/e2e/sprint1-2-ui-flows.mjs | J38: OK | K38: 2026-10-16 | L38: Mateo Pavoni | M38: OK en navegador real. Con el texto vacío el botón Guardar está deshabilitado y el modal sigue abierto.
A39: TC-38 | B39: Sprint 1-2 | C39: Casos manuales complementarios (Plan de Pruebas v1.2) | D39: Validar que no se agregue una entrada en blanco a la historia de vida | E39: Cubre la validación de la historia de vida (equivale a CP30 del Plan de Pruebas v1.2). | F39: Existe una ficha con la historia de vida de una etapa ya cargada. El usuario logueado tiene el rol Referente. | G39: EP-02 | H39: 1. Abrir Historia de vida y dejar el texto de una etapa vacío. → El campo de la etapa queda sin contenido. 2. Intentar guardar. → No se suma una entrada en blanco al historial de la etapa. | I39: docs/qa/e2e/sprint1-2-ui-flows.mjs | J39: OK | K39: 2026-10-16 | L39: Mateo Pavoni | M39: FALLÓ en la primera ejecución en navegador (DEF-27); corregido y re-ejecutado OK. Primera ejecución: con solo espacios el botón quedaba habilitado y la API respondía 400. Tras la corrección el botón queda deshabilitado.
A40: TC-39 | B40: Sprint 1-2 | C40: Casos manuales complementarios (Plan de Pruebas v1.2) | D40: Validar que el sistema se adapte a pantallas de celular | E40: Cubre el hallazgo H17 sobre responsividad: el menú lateral debe estar oculto por defecto en pantallas chicas (equivale a CP31 del Plan de Pruebas v1.2). | F40: Usuario con sesión iniciada. Navegador con un ancho de pantalla de aproximadamente 375 px. | G40: Transversal (H17) | H40: 1. Abrir el sistema en un ancho de unos 375 px. → El menú lateral queda oculto y se muestra un botón de hamburguesa. 2. Observar el contenido principal. → El contenido usa todo el ancho disponible de la pantalla. | I40: docs/qa/e2e/sprint1-2-ui-flows.mjs | J40: OK | K40: 2026-10-16 | L40: Mateo Pavoni | M40: OK en navegador real. En 390 px de ancho no hay desborde horizontal en el inicio ni en el listado de fichas.
...

Sheet Pasos TC
A1: ID | B1: # | C1: Paso | D1: Dato | E1: Esperamos
A2: TC-01 | B2: 1 | C2: Ingresar a la pantalla de Registro desde el login. | D2: — | E2: Se muestra el formulario de registro con los campos nombre, correo y contraseña.
A3: TC-01 | B3: 2 | C3: Completar los campos obligatorios y hacer clic en Registrarme. | D3: correo: ana.lopez@test.com | E3: El sistema crea la cuenta y muestra un mensaje de confirmación.
A4: TC-01 | B4: 3 | C4: Intentar iniciar sesión con las credenciales recién creadas. | D4: correo: ana.lopez@test.com | E4: El sistema informa que la cuenta está "Pendiente de aprobación" y no permite el acceso.
A5: TC-02 | B5: 1 | C5: Ingresar al panel de Gestión de Usuarios. | D5: — | E5: Se muestra el listado de cuentas con su estado (Pendiente / Activa / Desactivada).
A6: TC-02 | B6: 2 | C6: Seleccionar una cuenta con estado Pendiente y hacer clic en Aprobar. | D6: — | E6: El sistema habilita la selección de un rol para la cuenta.
A7: TC-02 | B7: 3 | C7: Seleccionar el rol Escucha y confirmar. | D7: rol: Escucha | E7: La cuenta pasa a estado "Activa" con el rol Escucha asignado.
A8: TC-03 | B8: 1 | C8: Ingresar el correo electrónico y la contraseña, y hacer clic en Entrar. | D8: correo: franco@hogar.org | E8: El sistema valida las credenciales y redirige al panel principal según el rol del usuario.
A9: TC-04 | B9: 1 | C9: Ingresar el correo válido con una contraseña incorrecta y hacer clic en Entrar. | D9: intento 1 a 4 | E9: El sistema rechaza el acceso e indica "Credenciales inválidas." (el sistema no revela cuál de los dos datos es incorrecto).
A10: TC-04 | B10: 2 | C10: Repetir el intento con contraseña incorrecta por quinta vez consecutiva. | D10: intento 5 | E10: El sistema bloquea la cuenta e informa que se alcanzó el máximo de intentos permitidos.
A11: TC-04 | B11: 3 | C11: Intentar iniciar sesión nuevamente con la contraseña correcta. | D11: — | E11: El sistema no permite el acceso mientras la cuenta permanezca bloqueada.
A12: TC-05 | B12: 1 | C12: Iniciar sesión con un usuario con rol Escucha. | D12: — | E12: El sistema muestra el panel correspondiente al rol Escucha.
A13: TC-05 | B13: 2 | C13: Abrir una ficha existente e intentar editar un dato personal. | D13: — | E13: El sistema no muestra opciones de edición sobre los datos de la ficha.
... A90: TC-40 | B90: 2 | C90: Elegir otra sección del menú. | D90: — | E90: El sistema navega a la sección elegida y el menú lateral se cierra automáticamente.

Sheet Parte B - Automatizados
A1: ID | B1: Sprint | C1: Módulo | D1: Título | E1: Description | F1: Pre-conditions | G1: Jira Requirement | H1: Pasos (Paso → Esperamos) | I1: Test (xUnit) | J1: Estado | K1: Fecha de ejecución | L1: Ejecutó
A2: TA-001 | B2: Sprint 1-2 | C2: Pruebas automatizadas — Registro, sesión y cuentas (EP-03) | D2: Validar que el registro con datos válidos responda 201 Created | E2: Registrar con email y password válidos crea la cuenta (201). | F2: API levantada con WebApplicationFactory. El email a registrar no existe. | G2: SCRUM-12 | H2: 1. Enviar POST /api/auth/register con nombre, apellido, email y contraseña válidos → La API crea la cuenta y responde 201 Created | I2: Vicaria.IntegrationTests › AuthControllerTests › Register_ConDatosValidos_Retorna201 | J2: OK | K2: 2026-10-14 | L2: Suite automatizada
A3: TA-002 | B3: Sprint 1-2 | C3: Pruebas automatizadas — Registro, sesión y cuentas (EP-03) | D3: Validar que el registro con un email mal formado sea rechazado | E3: Un email con formato inválido se rechaza (400). | F3: API levantada con WebApplicationFactory. | G3: SCRUM-12 | H3: 1. Enviar POST /api/auth/register con un email sin formato válido → La API rechaza el registro y responde 400 Bad Request | I3: Vicaria.IntegrationTests › AuthControllerTests › Register_ConEmailInvalido_Retorna400 | J3: OK | K3: 2026-10-14 | L3: Suite automatizada
A4: TA-003 | B4: Sprint 1-2 | C4: Pruebas automatizadas — Registro, sesión y cuentas (EP-03) | D4: Validar que el registro con una contraseña demasiado corta sea rechazado | E4: Una contraseña por debajo del mínimo se rechaza (400). | F4: API levantada con WebApplicationFactory. | G4: SCRUM-12 | H4: 1. Enviar POST /api/auth/register con una contraseña por debajo del mínimo → La API rechaza el registro y responde 400 Bad Request | I4: Vicaria.IntegrationTests › AuthControllerTests › Register_ConPasswordCorta_Retorna400 | J4: OK | K4: 2026-10-14 | L4: Suite automatizada
A5: TA-004 | B5: Sprint 1-2 | C5: Pruebas automatizadas — Registro, sesión y cuentas (EP-03) | D5: Validar que registrar dos veces el mismo email devuelva conflicto | E5: Registrar con un email ya existente devuelve conflicto (409). | F5: API levantada con WebApplicationFactory. | G5: SCRUM-12 | H5: 1. Registrar una cuenta con un email nuevo → La cuenta se crea (201) 2. Repetir el registro con el mismo email → La API responde 409 Conflict | I5: Vicaria.IntegrationTests › AuthControllerTests › Register_ConEmailYaRegistrado_Retorna409 | J5: OK | K5: 2026-10-14 | L5: Suite automatizada
A6: TA-005 | B6: Sprint 1-2 | C6: Pruebas automatizadas — Registro, sesión y cuentas (EP-03) | D6: Validar que consultar el perfil propio sin token no esté autorizado | E6: Consultar el perfil propio sin token no autoriza (401). | F6: API levantada con WebApplicationFactory. El cliente no envía token. | G6: SCRUM-33 | H6: 1. Enviar GET /api/auth/me sin encabezado de autorización → La API responde 401 Unauthorized | I6: Vicaria.IntegrationTests › AuthMeEndpointTests › Me_SinToken_Retorna401 | J6: OK | K6: 2026-10-14 | L6: Suite automatizada
A7: TA-006 | B7: Sprint 1-2 | C7: Pruebas automatizadas — Registro, sesión y cuentas (EP-03) | D7: Validar que un token inválido no permita consultar el perfil propio | E7: Un token inválido tampoco autoriza (401). | F7: API levantada con WebApplicationFactory. | G7: SCRUM-33 | H7: 1. Enviar GET /api/auth/me con un Bearer token inválido → La API responde 401 Unauthorized | I7: Vicaria.IntegrationTests › AuthMeEndpointTests › Me_ConTokenInvalido_Retorna401 | J7: OK | K7: 2026-10-14 | L7: Suite automatizada
A8: TA-007 | B8: Sprint 1-2 | C8: Pruebas automatizadas — Registro, sesión y cuentas (EP-03) | D8: Validar que con un token válido se devuelvan los datos del usuario logueado | E8: Con un token válido devuelve los datos del usuario logueado (200). | F8: Existe en la base un usuario activo con rol Directora de Casa de Convivencia y un JWT válido emitido para él. | G8: SCRUM-33 | H8: 1. Enviar GET /api/auth/me con el token válido → La API responde 200 OK 2. Revisar el cuerpo de la respuesta → Se devuelven los datos y el rol del usuario logueado | I8: Vicaria.IntegrationTests › AuthMeEndpointTests › Me_ConTokenValido_Retorna200ConLasClaims | J8: OK | K8: 2026-10-14 | L8: Suite automatizada
A9: TA-008 | B9: Sprint 1-2 | C9: Pruebas automatizadas — Registro, sesión y cuentas (EP-03) | D9: Validar que un usuario sin rol Referente no pueda listar cuentas pendientes | E9: Listar cuentas pendientes sin ser Referente no autoriza (403). | F9: Usuario autenticado con rol Escucha, existente en la base. | G9: SCRUM-12 | H9: 1. Enviar GET /api/auth/users/pending con el token del rol Escucha → La API responde 403 Forbidden | I9: Vicaria.IntegrationTests › UserApprovalEndpointTests › Pending_SinRolReferente_Retorna403 | J9: OK | K9: 2026-10-14 | L9: Suite automatizada
A10: TA-009 | B10: Sprint 1-2 | C10: Pruebas automatizadas — Registro, sesión y cuentas (EP-03) | D10: Validar que un Referente vea en pendientes a la cuenta recién registrada | E10: Un Referente ve en el listado a la cuenta recién registrada. | F10: Existe una cuenta recién registrada en estado Pendiente. Usuario autenticado con rol Referente. | G10: SCRUM-12 | H10: 1. Enviar GET /api/auth/users/pending con el token del Referente → La API responde 200 OK 2. Revisar el listado devuelto → El listado incluye la cuenta recién registrada | I10: Vicaria.IntegrationTests › UserApprovalEndpointTests › Pending_ConRolReferente_IncluyeElUsuarioRecienRegistrado | J10: OK | K10: 2026-10-14 | L10: Suite automatizada
A11: TA-010 | B11: Sprint 1-2 | C11: Pruebas automatizadas — Registro, sesión y cuentas (EP-03) | D11: Validar que aprobar un usuario inexistente devuelva 404 | E11: Aprobar un usuario inexistente devuelve 404. | F11: Usuario autenticado con rol Referente. Existe al menos un rol sembrado. | G11: SCRUM-12 | H11: 1. Enviar POST /api/auth/users/{id}/approve con un id que no existe → La API responde 404 Not Found | I11: Vicaria.IntegrationTests › UserApprovalEndpointTests › Approve_UsuarioNoExiste_Retorna404 | J11: OK | K11: 2026-10-14 | L11: Suite automatizada
A12: TA-011 | B12: Sprint 1-2 | C12: Pruebas automatizadas — Registro, sesión y cuentas (EP-03) | D12: Validar que un usuario que no es Referente no pueda aprobar cuentas | E12: Aprobar sin ser Referente no autoriza (403). | F12: Existe una cuenta Pendiente. Usuario autenticado con rol Directora de Casa de Convivencia. | G12: SCRUM-12 | H12: 1. Enviar POST /api/auth/users/{id}/approve con el token de la Directora → La API responde 403 Forbidden | I12: Vicaria.IntegrationTests › UserApprovalEndpointTests › Approve_SinRolReferente_Retorna403 | J12: OK | K12: 2026-10-14 | L12: Suite automatizada
... A238: TA-237 | B238: Sprint 3 | C238: Calendario general | D238: Validar: Mes más corto | E238: Respalda TC-138: Cae el último día de los meses de 30 días y de febrero (28 o 29) | F238: Servicio con DbContext InMemory. | G238: SCRUM-16 | H238: 1. Evento mensual del día 31 → Cae el último día de los meses de 30 días y de febrero (28 o 29) | I238: Vicaria.UnitTests › CalendarEventMonthlyRecurrenceTests › Expand_MonthlyEventOnDay31_UsesLeapDayInLeapYear | J238: OK | K238: 2026-10-14 | L238: Suite automatizada
A239: TA-238 | B239: Sprint 3 | C239: Calendario general | D239: Validar: Expand · MonthlyEvent · NeverReturnsDatesBeforeItsStart | E239: Sin TC manual asociado; descripción derivada del nombre del test. | F239: Servicio con DbContext InMemory. | G239: SCRUM-15 / SCRUM-16 | I239: Vicaria.UnitTests › CalendarEventMonthlyRecurrenceTests › Expand_MonthlyEvent_NeverReturnsDatesBeforeItsStart | J239: OK | K239: 2026-10-14 | L239: Suite automatizada
A240: TA-239 | B240: Sprint 3 | C240: Calendario general | D240: Validar: Expand · MonthlyEvent · RangeWithoutThatDayReturnsEmpty | E240: Sin TC manual asociado; descripción derivada del nombre del test. | F240: Servicio con DbContext InMemory. | G240: SCRUM-15 / SCRUM-16 | I240: Vicaria.UnitTests › CalendarEventMonthlyRecurrenceTests › Expand_MonthlyEvent_RangeWithoutThatDayReturnsEmpty | J240: OK | K240: 2026-10-14 | L240: Suite automatizada
A241: TA-240 | B241: Sprint 3 | C241: Calendario general | D241: Validar: Expand · WithoutMonthlyFlag · StillSingleDate | E241: Sin TC manual asociado; descripción derivada del nombre del test. | F241: Servicio con DbContext InMemory. | G241: SCRUM-15 / SCRUM-16 | I241: Vicaria.UnitTests › CalendarEventMonthlyRecurrenceTests › Expand_WithoutMonthlyFlag_StillSingleDate | J241: OK | K241: 2026-10-14 | L241: Suite automatizada
A242: TA-241 | B242: Sprint 3 | C242: Calendario general | D242: Validar: Expand · NullDateWithWeekdayFlags · ExpandsEveryMatchedDayInRange | E242: Sin TC manual asociado; descripción derivada del nombre del test. | F242: Servicio con DbContext InMemory. | G242: SCRUM-15 / SCRUM-16 | I242: Vicaria.UnitTests › CalendarEventOccurrenceExpanderTests › Expand_NullDateWithWeekdayFlags_ExpandsEveryMatchedDayInRange | J242: OK | K242: 2026-10-14 | L242: Suite automatizada
A243: TA-242 | B243: Sprint 3 | C243: Calendario general | D243: Validar: Expand · NullDateWithoutRecurrence · ReturnsEmpty | E243: Sin TC manual asociado; descripción derivada del nombre del test. | F243: Servicio con DbContext InMemory. | G243: SCRUM-15 / SCRUM-16 | I243: Vicaria.UnitTests › CalendarEventOccurrenceExpanderTests › Expand_NullDateWithoutRecurrence_ReturnsEmpty | J243: OK | K243: 2026-10-14 | L243: Suite automatizada
A244: TA-243 | B244: Sprint 3 | C244: Calendario general | D244: Validar: Expand · SingleDateWithoutRecurrence · ReturnsDateOnlyWhenInRange | E244: Sin TC manual asociado; descripción derivada del nombre del test. | F244: Servicio con DbContext InMemory. | G244: SCRUM-15 / SCRUM-16 | I244: Vicaria.UnitTests › CalendarEventOccurrenceExpanderTests › Expand_SingleDateWithoutRecurrence_ReturnsDateOnlyWhenInRange | J244: OK | K244: 2026-10-14 | L244: Suite automatizada
A245: TA-244 | B245: Sprint 3 | C245: Calendario general | D245: Validar: Expand · SeriesStartsOnStartDate · AndSkipsEarlierMatchedDays | E245: Sin TC manual asociado; descripción derivada del nombre del test. | F245: Servicio con DbContext InMemory. | G245: SCRUM-15 / SCRUM-16 | I245: Vicaria.UnitTests › CalendarEventOccurrenceExpanderTests › Expand_SeriesStartsOnStartDate_AndSkipsEarlierMatchedDays | J245: OK | K245: 2026-10-14 | L245: Suite automatizada
A246: TA-245 | B246: Sprint 3 | C246: Calendario general | D246: Validar: Expand · SeriesStartingBeforeRange · OnlyReturnsMatchedDaysInsideRange | E246: Sin TC manual asociado; descripción derivada del nombre del test. | F246: Servicio con DbContext InMemory. | G246: SCRUM-15 / SCRUM-16 | I246: Vicaria.UnitTests › CalendarEventOccurrenceExpanderTests › Expand_SeriesStartingBeforeRange_OnlyReturnsMatchedDaysInsideRange | J246: OK | K246: 2026-10-14 | L246: Suite automatizada
A247: TA-246 | B247: Sprint 3 | C247: Calendario general | D247: Validar: Expand · SeriesStartingAfterRange · ReturnsEmpty | E247: Sin TC manual asociado; descripción derivada del nombre del test. | F247: Servicio con DbContext InMemory. | G247: SCRUM-15 / SCRUM-16 | I247: Vicaria.UnitTests › CalendarEventOccurrenceExpanderTests › Expand_SeriesStartingAfterRange_ReturnsEmpty | J247: OK | K247: 2026-10-14 | L247: Suite automatizada
A248: TA-247 | B248: Sprint 3 | C248: Calendario general | D248: Validar: Expand · AppliedToWeekendOnlyEvent · OnlyMatchesWeekendDays | E248: Sin TC manual asociado; descripción derivada del nombre del test. | F248: Servicio con DbContext InMemory. | G248: SCRUM-15 / SCRUM-16 | I248: Vicaria.UnitTests › CalendarEventOccurrenceExpanderTests › Expand_AppliedToWeekendOnlyEvent_OnlyMatchesWeekendDays | J248: OK | K248: 2026-10-14 | L248: Suite automatizada
A249: TA-248 | B249: Sprint 3 | C249: Calendario general | D249: Validar: Editar evento (Referente) | E249: Respalda TC-100: 204; el detalle refleja el cambio; AuditLog "Evento general modificado" | F249: Servicio con DbContext InMemory. | G249: SCRUM-16 | H249: 1. PUT /api/general-calendar-events/{id} con nuevos datos → 204; el detalle refleja el cambio; AuditLog "Evento general modificado" | I249: Vicaria.UnitTests › GeneralCalendarEventOperationsTests › UpdateAsync_WhenAuthorUpdates_SucceedsAndLogsAudit | J249: OK | K249: 2026-10-14 | L249: Suite automatizada
A250: TA-249 | B250: Sprint 3 | C250: Calendario general | D250: Validar: Referente edita evento ajeno | E250: Respalda TC-101: 204 | F250: Servicio con DbContext InMemory. | G250: SCRUM-16 | H250: 1. PUT de un Referente sobre evento de otro autor → 204 | I250: Vicaria.UnitTests › GeneralCalendarEventOperationsTests › UpdateAsync_WhenReferentUpdatesOtherUsersEvent_SucceedsAndLogsAudit | J250: OK | K250: 2026-10-14 | L250: Suite automatizada
A251: TA-250 | B251: Sprint 3 | C251: Calendario general | D251: Validar: UpdateAsync · WhenNonAuthorAndNonReferentAttempts · ReturnsForbidden | E251: Sin TC manual asociado; descripción derivada del nombre del test. | F251: Servicio con DbContext InMemory. | G251: SCRUM-15 / SCRUM-16 | I251: Vicaria.UnitTests › GeneralCalendarEventOperationsTests › UpdateAsync_WhenNonAuthorAndNonReferentAttempts_ReturnsForbidden | J251: OK | K251: 2026-10-14 | L251: Suite automatizada
A252: TA-251 | B252: Sprint 3 | C252: Calendario general | D252: Validar: UpdateAsync · WhenEventNotFound · ReturnsNotFound | E252: Sin TC manual asociado; descripción derivada del nombre del test. | F252: Servicio con DbContext InMemory. | G252: SCRUM-15 / SCRUM-16 | I252: Vicaria.UnitTests › GeneralCalendarEventOperationsTests › UpdateAsync_WhenEventNotFound_ReturnsNotFound | J252: OK | K252: 2026-10-14 | L252: Suite automatizada
A253: TA-252 | B253: Sprint 3 | C253: Calendario general | D253: Validar: Eliminar evento | E253: Respalda TC-105: 204; el detalle pasa a 404; AuditLog "Evento general eliminado" | F253: Servicio con DbContext InMemory. | G253: SCRUM-16 | H253: 1. DELETE /api/general-calendar-events/{id} → 204; el detalle pasa a 404; AuditLog "Evento general eliminado" | I253: Vicaria.UnitTests › GeneralCalendarEventOperationsTests › DeleteAsync_WhenAuthorDeletes_SucceedsRemovesEntityAndLogsAudit | J253: OK | K253: 2026-10-14 | L253: Suite automatizada
A254: TA-253 | B254: Sprint 3 | C254: Calendario general | D254: Validar: DeleteAsync · WhenReferentDeletes · SucceedsRemovesEntityAndLogsAudit | E254: Sin TC manual asociado; descripción derivada del nombre del test. | F254: Servicio con DbContext InMemory. | G254: SCRUM-15 / SCRUM-16 | I254: Vicaria.UnitTests › GeneralCalendarEventOperationsTests › DeleteAsync_WhenReferentDeletes_SucceedsRemovesEntityAndLogsAudit | J254: OK | K254: 2026-10-14 | L254: Suite automatizada
A255: TA-254 | B255: Sprint 3 | C255: Calendario general | D255: Validar: DeleteAsync · WhenNonAuthorAndNonReferentAttempts · ReturnsForbidden | E255: Sin TC manual asociado; descripción derivada del nombre del test. | F255: Servicio con DbContext InMemory. | G255: SCRUM-15 / SCRUM-16 | I255: Vicaria.UnitTests › GeneralCalendarEventOperationsTests › DeleteAsync_WhenNonAuthorAndNonReferentAttempts_ReturnsForbidden | J255: OK | K255: 2026-10-14 | L255: Suite automatizada
A256: TA-255 | B256: Sprint 3 | C256: Calendario general | D256: Validar: DeleteAsync · WhenEventNotFound · ReturnsNotFound | E256: Sin TC manual asociado; descripción derivada del nombre del test. | F256: Servicio con DbContext InMemory. | G256: SCRUM-15 / SCRUM-16 | I256: Vicaria.UnitTests › GeneralCalendarEventOperationsTests › DeleteAsync_WhenEventNotFound_ReturnsNotFound | J256: OK | K256: 2026-10-14 | L256: Suite automatizada
A257: TA-256 | B257: Sprint 3 | C257: Calendario general | D257: Validar: CreateAsync · WithValidDto · PersistsEventWithAuthorAndUtcCreatedAt | E257: Sin TC manual asociado; descripción derivada del nombre del test. | F257: Servicio con DbContext InMemory. | G257: SCRUM-15 / SCRUM-16 | I257: Vicaria.UnitTests › GeneralCalendarEventServiceTests › CreateAsync_WithValidDto_PersistsEventWithAuthorAndUtcCreatedAt | J257: OK | K257: 2026-10-14 | L257: Suite automatizada
A258: TA-257 | B258: Sprint 3 | C258: Calendario general | D258: Validar: CreateAsync · WithValidDto · WritesAuditLogEntry | E258: Sin TC manual asociado; descripción derivada del nombre del test. | F258: Servicio con DbContext InMemory. | G258: SCRUM-15 / SCRUM-16 | I258: Vicaria.UnitTests › GeneralCalendarEventServiceTests › CreateAsync_WithValidDto_WritesAuditLogEntry | J258: OK | K258: 2026-10-14 | L258: Suite automatizada
A259: TA-258 | B259: Sprint 3 | C259: Calendario general | D259: Validar: CreateAsync · WithoutOptionalFields · PersistsNulls | E259: Sin TC manual asociado; descripción derivada del nombre del test. | F259: Servicio con DbContext InMemory. | G259: SCRUM-15 / SCRUM-16 | I259: Vicaria.UnitTests › GeneralCalendarEventServiceTests › CreateAsync_WithoutOptionalFields_PersistsNulls | J259: OK | K259: 2026-10-14 | L259: Suite automatizada
A260: TA-259 | B260: Sprint 3 | C260: Calendario general | D260: Validar: GetOccurrencesAsync · ExpandsTemplatesAndConcreteEvents | E260: Sin TC manual asociado; descripción derivada del nombre del test. | F260: Servicio con DbContext InMemory. | G260: SCRUM-15 / SCRUM-16 | I260: Vicaria.UnitTests › GeneralCalendarEventServiceTests › GetOccurrencesAsync_ExpandsTemplatesAndConcreteEvents | J260: OK | K260: 2026-10-14 | L260: Suite automatizada
A261: TA-260 | B261: Sprint 3 | C261: Calendario general | D261: Validar: GetOccurrencesAsync · PaginatesExpandedOccurrences | E261: Sin TC manual asociado; descripción derivada del nombre del test. | F261: Servicio con DbContext InMemory. | G261: SCRUM-15 / SCRUM-16 | I261: Vicaria.UnitTests › GeneralCalendarEventServiceTests › GetOccurrencesAsync_PaginatesExpandedOccurrences | J261: OK | K261: 2026-10-14 | L261: Suite automatizada
A262: TA-261 | B262: Sprint 3 | C262: Calendario general | D262: Validar: GetByIdAsync · ExistingEvent · ReturnsDetailWithAuthorName | E262: Sin TC manual asociado; descripción derivada del nombre del test. | F262: Servicio con DbContext InMemory. | G262: SCRUM-15 / SCRUM-16 | I262: Vicaria.UnitTests › GeneralCalendarEventServiceTests › GetByIdAsync_ExistingEvent_ReturnsDetailWithAuthorName | J262: OK | K262: 2026-10-14 | L262: Suite automatizada
A263: TA-262 | B263: Sprint 3 | C263: Calendario general | D263: Validar: GetByIdAsync · UnknownId · ReturnsNull | E263: Sin TC manual asociado; descripción derivada del nombre del test. | F263: Servicio con DbContext InMemory. | G263: SCRUM-15 / SCRUM-16 | I263: Vicaria.UnitTests › GeneralCalendarEventServiceTests › GetByIdAsync_UnknownId_ReturnsNull | J263: OK | K263: 2026-10-14 | L263: Suite automatizada
A264: TA-263 | B264: Sprint 3 | C264: Calendario personal | D264: Validar: Convertir personal a general | E264: Respalda TC-113: 200 con id del evento general; el personal desaparece; AuditLog | F264: Servicio con DbContext InMemory. | G264: SCRUM-17 | H264: 1. PUT /api/personal-calendar-events/{id}/publish → 200 con id del evento general; el personal desaparece; AuditLog | I264: Vicaria.UnitTests › PersonalCalendarEventPublishTests › PublishAsync_WhenAuthorPublishes_MovesEventToGeneralAndLogsAudit | J264: OK | K264: 2026-10-14 | L264: Suite automatizada
A265: TA-264 | B265: Sprint 3 | C265: Calendario personal | D265: Validar: Convertir evento ajeno o inexistente | E265: Respalda TC-114: 404 | F265: Servicio con DbContext InMemory. | G265: SCRUM-17 | H265: 1. PUT /publish de otro usuario / id desconocido → 404 | I265: Vicaria.UnitTests › PersonalCalendarEventPublishTests › PublishAsync_WhenEventBelongsToAnotherUser_ReturnsNotFoundAndDoesNotPublish | J265: OK | K265: 2026-10-14 | L265: Suite automatizada
...

Sheet Defectos y pendientes
A1: # | B1: Tipo | C1: Descripción | D1: Origen / Jira | E1: Estado | F1: Detalle
